Workbook

Sheet コスト表
B2: 概要 | C2: 内容 | D2: 詳細 | E2: 優先度 | F2: バージョン | G2: 作業工数 | H2: 実コスト | I2: 判定
B3: クラス設計 | E3: S | F3: プロト | G3: 4 | I3: 未着手
B4: ライブラリ設計 | E4: S | F4: プロト | G4: 4 | I4: 未着手
B5: アルファ素材集め | C5: プレイヤー | D5: プレイヤーの3Dモデル | E5: S | F5: プロト | G5: 2.5 | I5: 未着手
B6: アルファ素材集め | C6: プレイヤー | D6: プレイヤーの3Dアニメーション | E6: S | F6: プロト | G6: 2.5 | I6: 未着手
B7: アルファ素材集め | C7: 敵 | D7: 敵の3Dモデル | E7: S | F7: プロト | G7: 2.5 | I7: 未着手
B8: アルファ素材集め | C8: 敵 | D8: 敵の3Dアニメーション | E8: S | F8: プロト | G8: 2.5 | I8: 未着手
B9: アルファ素材集め | C9: UI | D9: UI | E9: A | F9: α | G9: 2 | I9: 未着手
B10: アルファ素材集め | C10: SE | D10: SE | E10: A | F10: α | G10: 2 | I10: 未着手
B11: アルファ素材集め | C11: BGM | D11: BGM | E11: A | F11: α | G11: 2 | I11: 未着手
B12: アルファ素材集め | C12: その他 | D12: その他 | E12: A | F12: α | G12: 1.5 | I12: 未着手
B13: 当たり判定 | C13: 当たり判定 | D13: カプセルの当たり判定 | E13: S | F13: プロト | G13: 2 | I13: 未着手
B14: 当たり判定 | C14: 当たり判定 | D14: 球の当たり判定 | E14: S | F14: プロト | G14: 2 | I14: 未着手
B15: 当たり判定 | C15: 当たり判定 | D15: 矩形の当たり判定 | E15: S | F15: プロト | G15: 2 | I15: 未着手
B16: 当たり判定 | C16: 当たり判定 | D16: ポリゴンの当たり判定 | E16: A | F16: プロト | G16: 2 | I16: 未着手
B17: プレイヤー | C17: プレイヤー共通 | D17: 移動 | E17: S | F17: プロト | G17: 0.5 | H17: 1 | I17: 未着手
B18: プレイヤー | C18: プレイヤー共通 | D18: 被弾 | E18: S | F18: プロト | G18: 0.5 | I18: 未着手
B19: プレイヤー | C19: プレイヤー共通 | D19: 死亡 | E19: S | F19: プロト | G19: 1 | I19: 未着手
B20: プレイヤー | C20: プレイヤー共通 | D20: 攻撃 | E20: S | F20: プロト | G20: 1.25 | I20: 未着手
B21: プレイヤー | C21: プレイヤー共通 | D21: バック | E21: S | F21: プロト | G21: 1 | I21: 未着手
B22: プレイヤー | C22: プレイヤー共通 | D22: ダッシュ | E22: S | F22: プロト | G22: 0.5 | I22: 未着手
B23: プレイヤー | C23: プレイヤー共通 | D23: ダッシュ | E23: S | F23: プロト | G23: 0.25 | H23: 0.25 | I23: 未着手
B24: プレイヤー | C24: プレイヤー共通 | D24: HP | E24: S | F24: プロト | G24: 0.5 | I24: 未着手
B25: プレイヤー | C25: プレイヤー共通 | D25: スキル1 | E25: S | F25: プロト | G25: 1 | I25: 未着手
B26: プレイヤー | C26: プレイヤー共通 | D26: スキル2 | E26: S | F26: プロト | G26: 1 | I26: 未着手
B27: プレイヤー | C27: プレイヤー共通 | D27: スキル3 | E27: S | F27: プロト | G27: 1 | I27: 未着手
B28: プレイヤー | C28: プレイヤー共通 | D28: スキル4 | E28: S | F28: プロト | G28: 1 | I28: 未着手
B29: プレイヤー | C29: プレイヤー共通 | D29: スキル5 | E29: S | F29: プロト | G29: 1 | I29: 未着手
B30: プレイヤー | C30: プレイヤー共通 | D30: スキル6 | E30: S | F30: プロト | G30: 1 | I30: 未着手
B31: プレイヤー | E31: C | F31: マスター | G31: 0 | I31: 未着手
B32: プレイヤー | E32: C | F32: マスター | G32: 0 | I32: 未着手
B33: プレイヤー | E33: C | F33: マスター | G33: 0 | I33: 未着手
B34: プレイヤー | E34: C | F34: マスター | G34: 0 | I34: 未着手
B35: プレイヤー | E35: C | F35: マスター | G35: 0 | I35: 未着手
B36: Boss | C36: Boss共通 | D36: 移動 | E36: S | F36: プロト | G36: 0 | I36: 未着手
B37: Boss | C37: Boss共通 | D37: 被弾 | E37: S | F37: プロト | G37: 0 | I37: 未着手
B38: Boss | C38: Boss共通 | D38: 死亡 | E38: S | F38: プロト | G38: 0 | I38: 未着手
B39: Boss | C39: Boss共通 | D39: 索敵 | E39: S | F39: プロト | G39: 0 | I39: 未着手
B40: Boss | C40: Boss共通 | D40: HP | E40: S | F40: プロト | G40: 0 | I40: 未着手
B41: Boss | C41: Boss共通 | D41: 近接攻撃 | E41: S | F41: プロト | G41: 0 | I41: 未着手
...

Sheet 作業状況
B2: 総コスト | C2: =SUM(コスト表!G3:G85) -> 55
B3: 消化コスト | C3: =SUMIF(コスト表!I3:I85,"完了",コスト表!G3:G85) -> 0 | D3: 消費コスト / 日数 | I3: 未完 | J3: 作業中 | K3: 作業停止中 | L3: バグ発生中 | M3: 機能削除 | N3: 完了
B4: 現在の日数(土日除く) | C4: =NETWORKDAYS(C5,C6) -> 262 | D4: =C3/ C4 -> 0 | H4: 全て | I4: =SUM(コスト表!G3:G85) -> 55 | J4: =SUMIF(コスト表!I3:I85,"作業中",コスト表!G3:G85) -> 0 | K4: =SUMIF(コスト表!I3:I85,"作業停止中",コスト表!G3:G85) -> 0 | L4: =SUMIF(コスト表!I3:I85,"バグ発生中",コスト表!G3:G85) -> 0 | M4: =SUMIF(コスト表!I3:I85,"機能削除",コスト表!G3:G85) -> 0 | N4: =SUMIF(コスト表!I3:I85,"完了",コスト表!G3:G85) -> 0
B5: 開始日 | C5: =DATE(2024,10,7) -> 45572 | H5: プロト | I5: =SUMIF(コスト表!F3:F85,"プロト",コスト表!G3:G85) -> 45.5 | J5: =SUMIFS(コスト表!G3:G85,コスト表!F3:F85,"プロト",コスト表!I3:I85,"作業中") -> 0 | K5: =SUMIFS(コスト表!G3:G85,コスト表!F3:F85,"プロト",コスト表!I3:I85,"作業停止中") -> 0 | L5: =SUMIFS(コスト表!G3:G85,コスト表!F3:F85,"プロト",コスト表!I3:I85,"バグ発生中") -> 0 | M5: =SUMIFS(コスト表!G3:G85,コスト表!F3:F85,"プロト",コスト表!I3:I85,"機能削除") -> 0 | N5: =SUMIFS(コスト表!G3:G85,コスト表!F3:F85,"プロト",コスト表!I3:I85,"完了") -> 0
B6: 今日の日付 | C6: =TODAY() -> 45937 | H6: α | I6: =SUMIF(コスト表!F3:F85,"α",コスト表!G3:G85) -> 7.5 | J6: =SUMIFS(コスト表!G3:G85,コスト表!F3:F85,"α",コスト表!I3:I85,"作業中") -> 0 | K6: =SUMIFS(コスト表!G3:G85,コスト表!F3:F85,"α",コスト表!I3:I85,"作業停止中") -> 0 | L6: =SUMIFS(コスト表!G3:G85,コスト表!F3:F85,"α",コスト表!I3:I85,"バグ発生中") -> 0 | M6: =SUMIFS(コスト表!G3:G85,コスト表!F3:F85,"α",コスト表!I3:I85,"機能削除") -> 0 | N6: =SUMIFS(コスト表!G3:G85,コスト表!F3:F85,"α",コスト表!I3:I85,"完了") -> 0
H7: β | I7: =SUMIF(コスト表!F3:F85,"β",コスト表!G3:G85) -> 0 | J7: =SUMIFS(コスト表!G3:G85,コスト表!F3:F85,"β",コスト表!I3:I85,"作業中") -> 0 | K7: =SUMIFS(コスト表!G3:G85,コスト表!F3:F85,"β",コスト表!I3:I85,"作業停止中") -> 0 | L7: =SUMIFS(コスト表!G3:G85,コスト表!F3:F85,"β",コスト表!I3:I85,"バグ発生中") -> 0 | M7: =SUMIFS(コスト表!G3:G85,コスト表!F3:F85,"β",コスト表!I3:I85,"機能削除") -> 0 | N7: =SUMIFS(コスト表!G3:G85,コスト表!F3:F85,"β",コスト表!I3:I85,"完了") -> 0
D8: 残り日数(土日除く) | E8: 一日の消費コスト | H8: マスター | I8: =SUMIF(コスト表!F3:F85,"マスター",コスト表!G3:G85) -> 2 | J8: =SUMIFS(コスト表!G3:G85,コスト表!F3:F85,"マスター",コスト表!I3:I85,"作業中") -> 0 | K8: =SUMIFS(コスト表!G3:G85,コスト表!F3:F85,"マスター",コスト表!I3:I85,"作業停止中") -> 0 | L8: =SUMIFS(コスト表!G3:G85,コスト表!F3:F85,"マスター",コスト表!I3:I85,"バグ発生中") -> 0 | M8: =SUMIFS(コスト表!G3:G85,コスト表!F3:F85,"マスター",コスト表!I3:I85,"機能削除") -> 0 | N8: =SUMIFS(コスト表!G3:G85,コスト表!F3:F85,"マスター",コスト表!I3:I85,"完了") -> 0
B9: 全て | C9: =DATE(2026,1,7) -> 46029 | D9: =NETWORKDAYS(TODAY(),C9) -> 67 | E9: =($C$2 - $C$3) / D9 -> 0.82089552
B10: プロト | C10: =DATE(2025,11,30) -> 45991 | D10: =NETWORKDAYS(TODAY(),C10) -> 39 | E10: =($I$5 - $N$5) / D10 -> 1.1666667
B11: α | C11: =DATE(2025,12,15) -> 46006 | D11: =NETWORKDAYS(TODAY(),C11) -> 50 | E11: =($I$6 - $N$6) / D11 -> 0.15
B12: β | C12: =DATE(2025,12,25) -> 46016 | D12: =NETWORKDAYS(TODAY(),C12) -> 58 | E12: =($I$7 - $N$7) / D12 -> 0
B13: マスター | C13: =DATE(2026,1,7) -> 46029 | D13: =NETWORKDAYS(TODAY(),C13) -> 67 | E13: =($I$8 - $N$8) / D13 -> 0.029850746
B16: S | C16: =SUMIF(コスト表!E3:E85,"S",コスト表!G3:G85) -> 45.5
B17: A | C17: =SUMIF(コスト表!E3:E85,"A",コスト表!G3:G85) -> 9.5
B18: B | C18: =SUMIF(コスト表!E3:E85,"B",コスト表!G3:G85) -> 0
B19: C | C19: =SUMIF(コスト表!E3:E85,"C",コスト表!G3:G85) -> 0
